Workbook

Sheet ASG Data
A1: VIRTUAL_MACHINE.ID | B1: VIRTUAL_MACHINE.Name | C1: VIRTUAL_MACHINE.Projects | D1: VIRTUAL_MACHINE.externalId | E1: VIRTUAL_MACHINE.operatingSystem | F1: VIRTUAL_MACHINE.status | G1: VIRTUAL_MACHINE.tags | H1: REGION.ID | I1: REGION.Name | J1: HOSTED_TECHNOLOGY.ID | K1: HOSTED_TECHNOLOGY.Name | L1: HOSTED_TECHNOLOGY.version | M1: SUBSCRIPTION.ID | N1: SUBSCRIPTION.Name | O1: SUBSCRIPTION.subscriptionId | P1: NETWORK_ADDRESS.ID | Q1: NETWORK_ADDRESS.Name | R1: ASG | S1: Cortex_Installed | T1: Tanium_Installed | U1: In_Scope_For_Action
A2: b9410a54-e35f-5804-ad08-a1ac1ab2d088 | B2: ue1pl-sh-mailout-asg | C2: AWS | D2: i-0463be3af2f02dfc4 | E2: Linux | F2: Active | G2: {"Availability":"24x7","Category":"traiana","CostCenter":"Osttra","DeploymentMethod":"Terragrunt","Deployment_Method":"Terragrunt","Description":"This resource is created for tpcore-dmz via terragrunt","Email":"osttra-cloud-enablement@osttra.com","Environment":"ue1p","Name":"ue1pl-sh-mailout-asg","Owner":"Cloud Engineering","Project":"tpcore-dmz","RepoUrl":"https://github.com/osttra/terraform-aws-tpcore-dmz-provisioning","aws:autoscaling:groupName":"ue1pl-sh-mailout-asg","aws:ec2launchtemplate:id":"lt-027c22c01f3cb1e96","aws:ec2launchtemplate:version":"7","fw_app":"mailout","fw_default":"true","fw_env":"prod","fw_nat":"shared"} | H2: 35f0e323-0818-5f67-a7c3-bf95849762e6 | I2: us-east-1 (767397888233) | J2: 041377d5-52cf-5548-b582-e8f66a3d7e7a | K2: Linux Red Hat (ue1pl-sh-mailout-asg) | L2: 9.5 | M2: 1103850b-f940-524b-a276-27930abe7533 | N2: aws-osttra-dmz-prod | O2: 767397888233 | P2: cb38f01b-cb4f-509b-9e51-4c2266ef506b | Q2: 10.195.54.19 | R2: ue1pl-sh-mailout-asg | S2: No | T2: Yes | U2: Yes
A3: b7ce9ccb-db13-56e7-b879-b9309b227ea5 | B3: ue1pl-sh-proxy-asg | C3: AWS | D3: i-05cc9ab4c83b819d9 | E3: Linux | F3: Active | G3: {"Availability":"24x7","Category":"traiana","CostCenter":"Osttra","DeploymentMethod":"Terragrunt","Deployment_Method":"Terragrunt","Description":"This resource is created for tpcore-dmz via terragrunt","Email":"osttra-cloud-enablement@osttra.com","Environment":"ue1p","Name":"ue1pl-sh-proxy-asg","Owner":"Cloud Engineering","Project":"tpcore-dmz","RepoUrl":"https://github.com/osttra/terraform-aws-tpcore-dmz-provisioning","aws:autoscaling:groupName":"ue1pl-sh-proxy-asg","aws:ec2launchtemplate:id":"lt-0b9c9ec11eb96d973","aws:ec2launchtemplate:version":"16","fw_app":"proxy","fw_default":"true","fw_env":"prod","fw_nat":"shared"} | H3: 35f0e323-0818-5f67-a7c3-bf95849762e6 | I3: us-east-1 (767397888233) | J3: 641bc669-0a1e-5a8c-8b00-448391e5f22b | K3: Linux Red Hat (ue1pl-sh-proxy-asg) | L3: 7.9 | M3: 1103850b-f940-524b-a276-27930abe7533 | N3: aws-osttra-dmz-prod | O3: 767397888233 | P3: 76e1c8f0-57be-5a13-9860-8b7a9cbcfe2d | Q3: 10.195.59.49 | R3: ue1pl-sh-proxy-asg | S3: Yes | T3: Yes | U3: No
A4: 8e150897-6280-5b6c-82a9-807d4056a4ab | B4: ue1pl-sh-proxy-asg | C4: AWS | D4: i-0b1b8b7eaa4bbdc13 | E4: Linux | F4: Active | G4: {"Availability":"24x7","Category":"traiana","CostCenter":"Osttra","DeploymentMethod":"Terragrunt","Deployment_Method":"Terragrunt","Description":"This resource is created for tpcore-dmz via terragrunt","Email":"osttra-cloud-enablement@osttra.com","Environment":"ue1p","Name":"ue1pl-sh-proxy-asg","Owner":"Cloud Engineering","Project":"tpcore-dmz","RepoUrl":"https://github.com/osttra/terraform-aws-tpcore-dmz-provisioning","aws:autoscaling:groupName":"ue1pl-sh-proxy-asg","aws:ec2launchtemplate:id":"lt-0b9c9ec11eb96d973","aws:ec2launchtemplate:version":"16","fw_app":"proxy","fw_default":"true","fw_env":"prod","fw_nat":"shared"} | H4: 35f0e323-0818-5f67-a7c3-bf95849762e6 | I4: us-east-1 (767397888233) | J4: 9d3d69dd-0247-5d2a-92c9-62175c5c3fe6 | K4: Linux Red Hat (ue1pl-sh-proxy-asg) | L4: 7.9 | M4: 1103850b-f940-524b-a276-27930abe7533 | N4: aws-osttra-dmz-prod | O4: 767397888233 | P4: f07e2746-4061-5caa-a65b-b3d31d6b9af8 | Q4: 10.195.54.55 | R4: ue1pl-sh-proxy-asg | S4: Yes | T4: Yes | U4: No
A5: dd8f9a8a-7732-5b4e-b595-2e3898ffcbb8 | B5: ue1pl-sh-mailout-asg | C5: AWS | D5: wiz-representative##arn:aws:autoscaling:us-east-1:767397888233:autoScalingGroup:65ba07bd-dca5-4e60-ae57-e76e2d55f067:autoScalingGroupName/ue1pl-sh-mailout-asg | E5: Linux | F5: Active | G5: {"Availability":"24x7","Category":"traiana","CostCenter":"Osttra","DeploymentMethod":"Terragrunt","Deployment_Method":"Terragrunt","Description":"This resource is created for tpcore-dmz via terragrunt","Email":"osttra-cloud-enablement@osttra.com","Environment":"ue1p","Name":"ue1pl-sh-mailout-asg","Owner":"Cloud Engineering","Project":"tpcore-dmz","RepoUrl":"https://github.com/osttra/terraform-aws-tpcore-dmz-provisioning","aws:autoscaling:groupName":"ue1pl-sh-mailout-asg","aws:ec2launchtemplate:id":"lt-027c22c01f3cb1e96","aws:ec2launchtemplate:version":"7","fw_app":"mailout","fw_default":"true","fw_env":"prod","fw_nat":"shared"} | H5: 35f0e323-0818-5f67-a7c3-bf95849762e6 | I5: us-east-1 (767397888233) | J5: 203a8cb9-1c3f-5818-b8d4-9ab773930fdc | K5: Linux Red Hat (ue1pl-sh-mailout-asg) | L5: 9.5 | M5: 1103850b-f940-524b-a276-27930abe7533 | N5: aws-osttra-dmz-prod | O5: 767397888233 | P5: ba7eff2c-aaf4-5bc4-b990-9c84fe59de67 | Q5: 10.195.59.22 | R5: ue1pl-sh-mailout-asg | S5: No | T5: Yes | U5: Yes
A6: ae531420-13b9-52b4-a10a-77b760a4cd1f | B6: ue2pl-sh-sftp-asg | C6: AWS | D6: i-025a59ea90f0bb1fd | E6: Linux | F6: Active | G6: {"Availability":"24x7","Category":"traiana","CostCenter":"Osttra","DeploymentMethod":"Terragrunt","Deployment_Method":"Terragrunt","Description":"This resource is created for tpcore-dmz via terragrunt","Email":"osttra-cloud-enablement@osttra.com","Environment":"ue2p","Name":"ue2pl-sh-sftp-asg","Owner":"Cloud Engineering","Project":"tpcore-dmz","RepoUrl":"https://github.com/osttra/terraform-aws-tpcore-dmz-provisioning","aws:autoscaling:groupName":"ue2pl-sh-sftp-asg","aws:ec2launchtemplate:id":"lt-016dedd48b1f66c57","aws:ec2launchtemplate:version":"8","fw_app":"sftp","fw_default":"true","fw_env":"prod","fw_nat":"shared"} | H6: d1052f70-beb0-5b2e-8d0b-2b78fe8a5820 | I6: us-east-2 (767397888233) | J6: f3f23c9d-7d59-5026-af5a-bd2999cf4441 | K6: Linux Red Hat (ue2pl-sh-sftp-asg) | L6: 9.5 | M6: 1103850b-f940-524b-a276-27930abe7533 | N6: aws-osttra-dmz-prod | O6: 767397888233 | P6: 82f9b8cf-bffb-5486-92ff-be143d79edcb | Q6: 10.188.138.78 | R6: ue2pl-sh-sftp-asg | S6: Yes | T6: Yes | U6: No
A7: a8fe30b4-db85-5347-93f3-ad9479f16bea | B7: ue2pl-sh-mailout-asg | C7: AWS | D7: i-03c17862ba04fbf32 | E7: Linux | F7: Active | G7: {"Availability":"24x7","Category":"traiana","CostCenter":"Osttra","DeploymentMethod":"Terragrunt","Deployment_Method":"Terragrunt","Description":"This resource is created for tpcore-dmz via terragrunt","Email":"osttra-cloud-enablement@osttra.com","Environment":"ue2p","Name":"ue2pl-sh-mailout-asg","Owner":"Cloud Engineering","Project":"tpcore-dmz","RepoUrl":"https://github.com/osttra/terraform-aws-tpcore-dmz-provisioning","aws:autoscaling:groupName":"ue2pl-sh-mailout-asg","aws:ec2launchtemplate:id":"lt-0c7209924d7d945ef","aws:ec2launchtemplate:version":"12","fw_app":"mailout","fw_default":"true","fw_env":"prod","fw_nat":"shared"} | H7: d1052f70-beb0-5b2e-8d0b-2b78fe8a5820 | I7: us-east-2 (767397888233) | J7: 7f2e4b0a-b2b7-5a8a-8e64-a58d21919e38 | K7: Linux Red Hat (ue2pl-sh-mailout-asg) | L7: 9.5 | M7: 1103850b-f940-524b-a276-27930abe7533 | N7: aws-osttra-dmz-prod | O7: 767397888233 | P7: 3fd7d98b-b7ff-5ef5-868f-a3826b161de9 | Q7: 10.188.137.31 | R7: ue2pl-sh-mailout-asg | S7: No | T7: No | U7: Yes
A8: 21a811d0-63e6-55b7-9e3d-890cee87c598 | B8: ue2pl-lh-mailin-asg | C8: AWS | D8: i-08d490f4baf525a8f | E8: Linux | F8: Active | G8: {"Availability":"24x7","Category":"traiana","CostCenter":"Osttra","DeploymentMethod":"Terragrunt","Deployment_Method":"Terragrunt","Description":"This resource is created for tpcore-dmz via terragrunt","Email":"osttra-cloud-enablement@osttra.com","Environment":"ue2p","Name":"ue2pl-lh-mailin-asg","Owner":"Cloud Engineering","Project":"tpcore-dmz","RepoUrl":"https://github.com/osttra/terraform-aws-tpcore-dmz-provisioning","aws:autoscaling:groupName":"ue2pl-lh-mailin-asg","aws:ec2launchtemplate:id":"lt-01dd2dd5fbab022a2","aws:ec2launchtemplate:version":"3","cost-center:app":"limithub","cost-center:category":"app","cost-center:email":"dl-limithub-development@osttra.com","cost-center:env":"prod","cost-center:owner":"limithub-team","fw_app":"mailin","fw_default":"true","fw_env":"prod","fw_nat":"shared"} | H8: d1052f70-beb0-5b2e-8d0b-2b78fe8a5820 | I8: us-east-2 (767397888233) | J8: 8e8b483d-d287-587e-8fd7-fdd00557657a | K8: Linux Red Hat (ue2pl-lh-mailin-asg) | L8: 9.4 | M8: 1103850b-f940-524b-a276-27930abe7533 | N8: aws-osttra-dmz-prod | O8: 767397888233 | P8: 8f4bd143-d904-5e11-8d44-67eee1edf3f9 | Q8: 10.188.136.215 | R8: ue2pl-lh-mailin-asg | S8: Yes | T8: Yes | U8: No
A9: 3c3a7e3a-ad03-5b34-8e1c-98f98f298179 | B9: ue2pl-sh-proxy-asg | C9: AWS | D9: i-0b784446d7551d408 | E9: Linux | F9: Active | G9: {"Availability":"24x7","Category":"traiana","CostCenter":"Osttra","DeploymentMethod":"Terragrunt","Deployment_Method":"Terragrunt","Description":"This resource is created for tpcore-dmz via terragrunt","Email":"osttra-cloud-enablement@osttra.com","Environment":"ue2p","Name":"ue2pl-sh-proxy-asg","Owner":"Cloud Engineering","Project":"tpcore-dmz","RepoUrl":"https://github.com/osttra/terraform-aws-tpcore-dmz-provisioning","aws:autoscaling:groupName":"ue2pl-sh-proxy-asg","aws:ec2launchtemplate:id":"lt-001581c3d510a9ad5","aws:ec2launchtemplate:version":"11","fw_app":"proxy","fw_default":"true","fw_env":"prod","fw_nat":"shared"} | H9: d1052f70-beb0-5b2e-8d0b-2b78fe8a5820 | I9: us-east-2 (767397888233) | J9: 318c6b7a-96ab-5156-9202-12a19d7b1cf8 | K9: Linux Red Hat (ue2pl-sh-proxy-asg) | L9: 7.9 | M9: 1103850b-f940-524b-a276-27930abe7533 | N9: aws-osttra-dmz-prod | O9: 767397888233 | P9: 9ef0da09-e26b-5320-aa18-2cc570683639 | Q9: 10.188.135.71 | R9: ue2pl-sh-proxy-asg | S9: Yes | T9: Yes | U9: No
A10: 2a00371a-3f12-591e-b6ab-5a3d3ef68b55 | B10: ue2pl-adp1-asg | C10: AWS | D10: i-0cc89b577ce173551 | E10: Linux | F10: Active | G10: {"Availability":"24x7","Category":"traiana","CostCenter":"Osttra","DeploymentMethod":"Terragrunt","Deployment_Method":"Terragrunt","Description":"This resource is created for tpcore-dmz via terragrunt","Email":"osttra-cloud-enablement@osttra.com","Environment":"ue2p","Name":"ue2pl-adp1-asg","Owner":"Cloud Engineering","Project":"tpcore-dmz","RepoUrl":"https://github.com/osttra/terraform-aws-tpcore-dmz-provisioning","aws:autoscaling:groupName":"ue2pl-adp1-asg","aws:ec2launchtemplate:id":"lt-027c3240d98aca6ca","aws:ec2launchtemplate:version":"2","fw_app":"adapters","fw_default":"true","fw_env":"prod","fw_nat":"shared"} | H10: d1052f70-beb0-5b2e-8d0b-2b78fe8a5820 | I10: us-east-2 (767397888233) | J10: c7f0dd37-e55a-5323-8d00-c9aa9faab14c | K10: Linux Red Hat (ue2pl-adp1-asg) | L10: 7.9 | M10: 1103850b-f940-524b-a276-27930abe7533 | N10: aws-osttra-dmz-prod | O10: 767397888233 | P10: 5cacabdc-f10a-5f4c-82de-570b830aedd0 | Q10: 10.188.139.36 | R10: ue2pl-adp1-asg | S10: Yes | T10: Yes | U10: No
A11: 06fe2dfc-a76f-5562-b048-26014944107e | B11: ue2pl-lh-sftp-asg | C11: AWS | D11: i-0cddd2fb9f4ec4ef9 | E11: Linux | F11: Active | G11: {"Availability":"24x7","Category":"traiana","CostCenter":"Osttra","DeploymentMethod":"Terragrunt","Deployment_Method":"Terragrunt","Description":"This resource is created for tpcore-dmz via terragrunt","Email":"osttra-cloud-enablement@osttra.com","Environment":"ue2p","Name":"ue2pl-lh-sftp-asg","Owner":"Cloud Engineering","Project":"tpcore-dmz","RepoUrl":"https://github.com/osttra/terraform-aws-tpcore-dmz-provisioning","aws:autoscaling:groupName":"ue2pl-lh-sftp-asg","aws:ec2launchtemplate:id":"lt-008af5017d91e6f45","aws:ec2launchtemplate:version":"7","cost-center:app":"limithub","cost-center:category":"app","cost-center:email":"dl-limithub-development@osttra.com","cost-center:env":"prod","cost-center:owner":"limithub-team","fw_app":"sftp","fw_default":"true","fw_env":"prod","fw_nat":"limithub"} | H11: d1052f70-beb0-5b2e-8d0b-2b78fe8a5820 | I11: us-east-2 (767397888233) | J11: e4fbb80a-7c86-5aa5-804e-08aa092334cb | K11: Linux Red Hat (ue2pl-lh-sftp-asg) | L11: 9.5 | M11: 1103850b-f940-524b-a276-27930abe7533 | N11: aws-osttra-dmz-prod | O11: 767397888233 | P11: 29ae06a8-a9d6-5057-8143-aac556abbf08 | Q11: 10.188.138.7 | R11: ue2pl-lh-sftp-asg | S11: Yes | T11: Yes | U11: No
A12: bde56606-5bc2-5419-9ae9-cd709ebc4b63 | B12: ue2pl-sh-sftp-asg | C12: AWS | D12: wiz-representative##arn:aws:autoscaling:us-east-2:767397888233:autoScalingGroup:61b93537-1565-49c2-8338-78581d96e8ac:autoScalingGroupName/ue2pl-sh-sftp-asg | E12: Linux | F12: Active | G12: {"Availability":"24x7","Category":"traiana","CostCenter":"Osttra","DeploymentMethod":"Terragrunt","Deployment_Method":"Terragrunt","Description":"This resource is created for tpcore-dmz via terragrunt","Email":"osttra-cloud-enablement@osttra.com","Environment":"ue2p","Name":"ue2pl-sh-sftp-asg","Owner":"Cloud Engineering","Project":"tpcore-dmz","RepoUrl":"https://github.com/osttra/terraform-aws-tpcore-dmz-provisioning","aws:autoscaling:groupName":"ue2pl-sh-sftp-asg","aws:ec2launchtemplate:id":"lt-016dedd48b1f66c57","aws:ec2launchtemplate:version":"8","fw_app":"sftp","fw_default":"true","fw_env":"prod","fw_nat":"shared"} | H12: d1052f70-beb0-5b2e-8d0b-2b78fe8a5820 | I12: us-east-2 (767397888233) | J12: 6d322e18-9c67-5aa5-a3b7-36772006ca8a | K12: Linux Red Hat (ue2pl-sh-sftp-asg) | L12: 9.5 | M12: 1103850b-f940-524b-a276-27930abe7533 | N12: aws-osttra-dmz-prod | O12: 767397888233 | P12: c0dc2724-da83-5da7-a6cd-07235701f273 | Q12: 10.188.134.149 | R12: ue2pl-sh-sftp-asg | S12: Yes | T12: Yes | U12: No
A13: b80f2d0e-abcc-5ad3-b81d-8a4f0e33a175 | B13: ue2pl-adp2-asg | C13: AWS | D13: wiz-representative##arn:aws:autoscaling:us-east-2:767397888233:autoScalingGroup:660edc02-e932-47d4-abc4-415143c135ae:autoScalingGroupName/ue2pl-adp2-asg | E13: Linux | F13: Active | G13: {"Availability":"24x7","Category":"traiana","CostCenter":"Osttra","DeploymentMethod":"Terragrunt","Deployment_Method":"Terragrunt","Description":"This resource is created for tpcore-dmz via terragrunt","Email":"osttra-cloud-enablement@osttra.com","Environment":"ue2p","Name":"ue2pl-adp2-asg","Owner":"Cloud Engineering","Project":"tpcore-dmz","RepoUrl":"https://github.com/osttra/terraform-aws-tpcore-dmz-provisioning","aws:autoscaling:groupName":"ue2pl-adp2-asg","aws:ec2launchtemplate:id":"lt-0fc4c121bf56791af","aws:ec2launchtemplate:version":"1","fw_app":"adapters","fw_default":"true","fw_env":"prod","fw_nat":"shared"} | H13: d1052f70-beb0-5b2e-8d0b-2b78fe8a5820 | I13: us-east-2 (767397888233) | J13: f7ace7a8-b23a-55f3-81a1-ad31ce4bb856 | K13: Linux Red Hat (ue2pl-adp2-asg) | L13: 7.9 | M13: 1103850b-f940-524b-a276-27930abe7533 | N13: aws-osttra-dmz-prod | O13: 767397888233 | P13: 84604c24-99b1-5c7b-8952-e4406c132b57 | Q13: 10.188.138.253 | R13: ue2pl-adp2-asg | S13: Yes | T13: Yes | U13: No
... A180: 53f5677c-8fed-5d30-a46a-fb385ef86fd0 | B180: Artifactory-Slave | C180: AWS | D180: wiz-representative##arn:aws:autoscaling:us-east-1:213297043725:autoScalingGroup:67bed2f7-5d34-4d65-a9cb-6cdb6b4b02a6:autoScalingGroupName/artifactory-slaves | E180: Linux | F180: Active | G180: {"Name":"Artifactory-Slave","application-name":"artifactory","aws:autoscaling:groupName":"artifactory-slaves","aws:ec2launchtemplate:id":"lt-0f66f5589c61a226e","aws:ec2launchtemplate:version":"24","businessgroup":"optimization","deployment-method":"terraform","operational-hours":"247","organization":"traiana","owner":"DevOps","owner-email":"devops-ci@traiana.com","repo-url":"https://github.com/traiana/tf-jfrog.git"} | H180: 811f7b02-eee7-5178-87fb-f32cc2dd4f7c | I180: us-east-1 (213297043725) | J180: 794bb882-5385-5aad-ae59-84c788c6d4e9 | K180: Amazon Linux 1 (Artifactory-Slave) | L180: AMI release 2018.03 | M180: 922f246f-f695-521b-865d-240987bac080 | N180: aws-us-infinity-services | O180: 213297043725 | P180: 0f615d58-ddb2-5514-b97c-ef14711824ce | Q180: 10.165.16.211 | R180: artifactory-slaves | S180: No | T180: No | U180: Yes

Sheet ASG Pivot
G3: owner | H3: update
G4: Udit/Dinesh
G5: network
G6: Himanshu
G7: network | H7: already communicated to network team
G8: network | H8: already communicated to network team
G9: network | H9: already communicated to network team
G10: network | H10: already communicated to network team
G11: Dinesh Kumar
G12: Dinesh Kumar | H12: installed and rolled to AMI
G13: Dinesh Kumar | H13: not exist anymore
G15: Dinesh Kumar | H15: will be decomissioned on weekend
G16: Christian Leigh | H16: mail dropped
G18: Dinesh Kumar | H18: installed and rolled to AMI
G19: Shivam | H19: mail dropped
G20: Shivam | H20: mail dropped
G21: Shivam | H21: mail dropped
G22: No Info
G23: No Info
G24: No Info
G25: No Info
G26: Dinesh Kumar | H26: installed and rolled out
G27: Dinesh Kumar
G28: Dinesh Kumar | H28: As per cloud team it will be terminated soon.
G29: Dinesh Kumar
G30: Dinesh Kumar
G32: Dinesh Kumar
G33: Dinesh Kumar
G34: Dinesh Kumar
G35: Dinesh Kumar
G36: Dinesh Kumar
G37: Christian Leigh | H37: mail dropped
G39: Dinesh Kumar
G40: Dinesh Kumar
G41: No Info
G42: No Info
G43: No Info
G44: No Info
G46: Christian Leigh | H46: mail dropped
G47: Himanshu Bansal
...

Sheet Detail19-aws-osttra-network
A1: VIRTUAL_MACHINE.ID | B1: VIRTUAL_MACHINE.Name | C1: VIRTUAL_MACHINE.Projects | D1: VIRTUAL_MACHINE.externalId | E1: VIRTUAL_MACHINE.operatingSystem | F1: VIRTUAL_MACHINE.status | G1: VIRTUAL_MACHINE.tags | H1: REGION.ID | I1: REGION.Name | J1: HOSTED_TECHNOLOGY.ID | K1: HOSTED_TECHNOLOGY.Name | L1: HOSTED_TECHNOLOGY.version | M1: SUBSCRIPTION.ID | N1: SUBSCRIPTION.Name | O1: SUBSCRIPTION.subscriptionId | P1: NETWORK_ADDRESS.ID | Q1: NETWORK_ADDRESS.Name | R1: ASG | S1: Cortex_Installed | T1: Tanium_Installed | U1: In_Scope_For_Action
A2: 9c265fd3-a18f-5f9f-982c-37cf4b3c6731 | B2: Linux-bastion-host-eu-west-1 | C2: AWS, Networking | D2: i-0ae6a9c8b689d4f91 | E2: Linux | F2: Active | G2: {"CostCenter":"Osttra","DeploymentMethod":"Terragrunt","Description":"This resource is created for osttra-network via terraform or terragrunt","Email":"network@osttra.com","Environment":"PROD","Name":"Linux-bastion-host-eu-west-1","Owner":"osttra-network","Project":"osttra-network","RepoUrl":"https://github.com/osttra/aws-network-deploy","aws:autoscaling:groupName":"bastion-host-asg-eu-west-1","aws:ec2launchtemplate:id":"lt-084122f6925d72c5a","aws:ec2launchtemplate:version":"2"} | H2: 57553cad-b73c-5cf7-a1de-ce0558cc0ba7 | I2: eu-west-1 (161441385277) | J2: a26ab0f9-c2ed-51f5-8a59-b59ff60bdb6d | K2: Linux Red Hat (Linux-bastion-host-eu-west-1) | L2: 8.10 | M2: a918d5cb-5ffb-508d-93bd-76abaf4294b5 | N2: aws-osttra-network | O2: 161441385277 | P2: dc64237d-6f7d-5674-8635-3cd87da08b95 | Q2: 10.196.253.80 | R2: bastion-host-asg-eu-west-1 | S2: No | T2: No | U2: Yes
A3: 03c51047-9f6a-5f57-be7d-91e03396af11 | B3: zabbix-server-us-east-1-poc | C3: AWS, Networking | D3: i-00f418462c52d7f9c | E3: Linux | F3: Active | G3: {"CostCenter":"Osttra","DeploymentMethod":"Terragrunt","Description":"This resource is created for osttra-network via terraform or terragrunt","Email":"network@osttra.com","Environment":"PROD","Name":"zabbix-server-us-east-1-poc","Owner":"osttra-network","Project":"osttra-network","RepoUrl":"https://github.com/osttra/aws-network-deploy","aws:autoscaling:groupName":"zabbix-server-asg-us-east-1","aws:ec2launchtemplate:id":"lt-0f95986b3a7cf51f5","aws:ec2launchtemplate:version":"1"} | H3: afc6b70e-66a3-5a28-87db-9c030a4112c1 | I3: us-east-1 (161441385277) | J3: b5729854-04a5-50b8-926d-3fd6df7c9b1b | K3: Linux Ubuntu (zabbix-server-us-east-1-poc) | L3: 22.04.5 | M3: a918d5cb-5ffb-508d-93bd-76abaf4294b5 | N3: aws-osttra-network | O3: 161441385277 | P3: 21cda7f1-4ff5-55db-ac36-c4db16384e9c | Q3: 10.196.72.168 | R3: zabbix-server-asg-us-east-1 | S3: No | T3: No | U3: Yes
A4: c39c4759-1146-5d73-b1c5-224e53f2b448 | B4: Linux-bastion-host-us-east-1 | C4: AWS, Networking | D4: i-0706c3c96d457fe30 | E4: Linux | F4: Active | G4: {"CostCenter":"Osttra","DeploymentMethod":"Terragrunt","Description":"This resource is created for osttra-network via terraform or terragrunt","Email":"network@osttra.com","Environment":"PROD","Name":"Linux-bastion-host-us-east-1","Owner":"osttra-network","Project":"osttra-network","RepoUrl":"https://github.com/osttra/aws-network-deploy","aws:autoscaling:groupName":"bastion-host-asg-us-east-1","aws:ec2launchtemplate:id":"lt-0959a24fb2017fbff","aws:ec2launchtemplate:version":"5"} | H4: afc6b70e-66a3-5a28-87db-9c030a4112c1 | I4: us-east-1 (161441385277) | J4: 754adc65-631e-5d43-b742-3afdaf58372a | K4: Linux Red Hat (Linux-bastion-host-us-east-1) | L4: 8.10 | M4: a918d5cb-5ffb-508d-93bd-76abaf4294b5 | N4: aws-osttra-network | O4: 161441385277 | P4: 64fd49f6-bdde-5bd9-9e3a-3860dd0de8db | Q4: 10.196.72.189 | R4: bastion-host-asg-us-east-1 | S4: No | T4: No | U4: Yes
A5: ae1a6d31-0a6d-570c-982d-5917b65c94da | B5: grafana-server-us-east-1 | C5: AWS, Networking | D5: i-0a76a4f523f600c2a | E5: Linux | F5: Active | G5: {"CostCenter":"Osttra","DeploymentMethod":"Terragrunt","Description":"This resource is created for osttra-network via terraform or terragrunt","Email":"network@osttra.com","Environment":"PROD","Name":"grafana-server-us-east-1","Owner":"osttra-network","Project":"osttra-network","RepoUrl":"https://github.com/osttra/aws-network-deploy","aws:autoscaling:groupName":"grafana-server-asg-us-east-1","aws:ec2launchtemplate:id":"lt-0104bd9a71ee3ba24","aws:ec2launchtemplate:version":"1"} | H5: afc6b70e-66a3-5a28-87db-9c030a4112c1 | I5: us-east-1 (161441385277) | J5: 5f256430-3e1e-540b-b9a1-afcdcaa004c6 | K5: Linux Ubuntu (grafana-server-us-east-1) | L5: 22.04.5 | M5: a918d5cb-5ffb-508d-93bd-76abaf4294b5 | N5: aws-osttra-network | O5: 161441385277 | P5: 7479b426-e83c-5d0a-a5a5-ca5ba815756a | Q5: 10.196.72.167 | R5: grafana-server-asg-us-east-1 | S5: No | T5: No | U5: Yes
O11: aws-osttra-network | P11: 10.196.253.80
O12: aws-osttra-network | P12: 10.196.72.168
O13: aws-osttra-network | P13: 10.196.72.189
O14: aws-osttra-network | P14: 10.196.72.167

Sheet Non-ASG Data
A1: VIRTUAL_MACHINE.ID | B1: VIRTUAL_MACHINE.Name | C1: comment | D1: VIRTUAL_MACHINE.Projects | E1: VIRTUAL_MACHINE.externalId | F1: VIRTUAL_MACHINE.operatingSystem | G1: VIRTUAL_MACHINE.status | H1: VIRTUAL_MACHINE.tags | I1: REGION.ID | J1: REGION.Name | K1: HOSTED_TECHNOLOGY.ID | L1: HOSTED_TECHNOLOGY.Name | M1: HOSTED_TECHNOLOGY.version | N1: SUBSCRIPTION.ID | O1: SUBSCRIPTION.Name | P1: SUBSCRIPTION.subscriptionId | Q1: NETWORK_ADDRESS.ID | R1: NETWORK_ADDRESS.Name | S1: Cortex_Installed | T1: Tanium_Installed | U1: In_Scope_For_Action
A2: fde5e7aa-eb23-521c-8643-d789d0c010c3 | B2: testing-connectivuty-issue | C2: cloud ticket raised i we do not have sufficient access(CLOUD-9647) | D2: AWS | E2: i-074a48410c71eec10 | F2: Linux | G2: Active | H2: {"Name":"testing-connectivuty-issue"} | I2: 4a9cdc45-40b2-53a9-9a2e-94c923b36e0f | J2: us-east-1 (242201293832) | K2: e6681d9d-ba7c-5ba4-b1c9-55c0fddad00c | L2: Amazon Linux 2023 (testing-connectivuty-issue) | M2: 2023.6.20250218 (Amazon Linux) | N2: 5e0a79f2-3265-55a3-80d3-39e7c41e1466 | O2: aws-aas-uat | P2: 242201293832 | Q2: fb3ecc75-fa51-50f7-83df-912856289240 | R2: 10.135.40.151 | S2: No | T2: No | U2: Yes
A3: c50c295e-64e1-5b79-ac86-b5027e39910b | B3: osttra-dnm-dev-emr-instances | C3: installed | D3: AWS | E3: i-0f5b03ffce7b6f255 | F3: Linux | G3: Active | H3: {"Category":"credit risk","CostCenter":"Osttra","Deployment_Method":"Terragrunt","Description":"this resource is created for dnm via terraform or terragrunt","Email":"shiva.sharma@osttra.com","Environment":"dev","Name":"osttra-dnm-dev-emr-instances","Owner":"Shiva Sharma","Project":"dnm","RepoUrl":"https://github.com/osttra/terraform-dnm-provisioning","Teams":"CloudEng","aws:elasticmapreduce:instance-group-role":"MASTER","aws:elasticmapreduce:job-flow-id":"j-DM7KMQZXC5WQ"} | I3: b04a10e1-1e0f-5263-8fc3-ab554b486ae1 | J3: us-east-1 (083892454888) | K3: 8ad2e62d-f854-5562-9ec7-0a6e22eda807 | L3: Amazon Linux 2023 (osttra-dnm-dev-emr-instances) | M3: 2023.5.20240819 (Amazon Linux) | N3: 94bd2043-78ee-5ad4-83c4-2d5e29facf2e | O3: aws-cr-dev | P3: 083892454888 | Q3: a018819c-a353-50e2-8e71-acecd5007cbe | R3: 10.133.164.223 | S3: Yes | T3: Yes | U3: no
A4: a57a07d4-0411-5646-a4b7-ad2d435db9de | B4: osttra-dnm-dev-emr-instances | C4: installed | D4: AWS | E4: wiz-representative##Ephemeral_aws:elasticmapreduce:job-flow-id_j-DM7KMQZXC5WQ | F4: Linux | G4: Active | H4: {"Category":"credit risk","CostCenter":"Osttra","Deployment_Method":"Terragrunt","Description":"this resource is created for dnm via terraform or terragrunt","Email":"shiva.sharma@osttra.com","Environment":"dev","Name":"osttra-dnm-dev-emr-instances","Owner":"Shiva Sharma","Project":"dnm","RepoUrl":"https://github.com/osttra/terraform-dnm-provisioning","Teams":"CloudEng","aws:elasticmapreduce:instance-group-role":"MASTER","aws:elasticmapreduce:job-flow-id":"j-DM7KMQZXC5WQ"} | I4: b04a10e1-1e0f-5263-8fc3-ab554b486ae1 | J4: us-east-1 (083892454888) | K4: 6952fc57-5b27-5272-944c-9bf08e536814 | L4: Amazon Linux 2023 (osttra-dnm-dev-emr-instances) | M4: 2023.5.20240819 (Amazon Linux) | N4: 94bd2043-78ee-5ad4-83c4-2d5e29facf2e | O4: aws-cr-dev | P4: 083892454888 | Q4: 6cfa2b74-cb7c-5cee-b69d-0e95af22110f | R4: 10.133.164.158, 10.133.164.163, 10.133.164.243 | S4: no | T4: no | U4: Yes
A5: 60f66b6c-a391-5817-8fba-cb3ec3ad616b | B5: osttra-dnm-qa-emr-instances | C5: cloud ticket raised i we do not have sufficient access(CLOUD-9647) | D5: AWS | E5: i-073b9daf71476511a | F5: Linux | G5: Active | H5: {"Category":"credit risk","CostCenter":"Osttra","Deployment_Method":"Terragrunt","Description":"this resource is created for dnm via terraform or terragrunt","Email":"shiva.sharma@osttra.com","Environment":"qa","Name":"osttra-dnm-qa-emr-instances","Owner":"Shiva Sharma","Project":"dnm","RepoUrl":"https://github.com/osttra/terraform-dnm-provisioning","aws:elasticmapreduce:instance-group-role":"MASTER","aws:elasticmapreduce:job-flow-id":"j-33DTR9YZ28RDE"} | I5: 937c7e1e-a7c8-5e84-8af0-f4d3c00d50bc | J5: us-east-1 (943395393854) | K5: ec2796be-f478-56eb-a861-0bfda68ec5e2 | L5: Amazon Linux 2023 (osttra-dnm-qa-emr-instances) | M5: 2023.6.20241121 (Amazon Linux) | N5: 71e8284d-9e3a-53d6-b933-6eba62f7a697 | O5: aws-cr-qa | P5: 943395393854 | Q5: 018eb9f7-83ab-51b1-b3d1-8b748aef7af8 | R5: 10.133.166.53 | S5: yes | T5: yes | U5: no
A6: 0f4602eb-2566-5fe8-9b2a-25976d91a3c0 | B6: osttra-dnm-qa-emr-instances | C6: cloud ticket raised i we do not have sufficient access(CLOUD-9647) | D6: AWS | E6: wiz-representative##Ephemeral_aws:elasticmapreduce:job-flow-id_j-33DTR9YZ28RDE | F6: Linux | G6: Active | H6: {"Category":"credit risk","CostCenter":"Osttra","Deployment_Method":"Terragrunt","Description":"this resource is created for dnm via terraform or terragrunt","Email":"shiva.sharma@osttra.com","Environment":"qa","Name":"osttra-dnm-qa-emr-instances","Owner":"Shiva Sharma","Project":"dnm","RepoUrl":"https://github.com/osttra/terraform-dnm-provisioning","aws:elasticmapreduce:instance-group-role":"MASTER","aws:elasticmapreduce:job-flow-id":"j-33DTR9YZ28RDE"} | I6: 937c7e1e-a7c8-5e84-8af0-f4d3c00d50bc | J6: us-east-1 (943395393854) | K6: d5166a76-7727-54cb-9402-a58f6bb4b85a | L6: Amazon Linux 2023 (osttra-dnm-qa-emr-instances) | M6: 2023.6.20241121 (Amazon Linux) | N6: 71e8284d-9e3a-53d6-b933-6eba62f7a697 | O6: aws-cr-qa | P6: 943395393854 | Q6: 2056e4fc-68ed-5cc0-a48c-4792b7704d54 | R6: 10.133.166.11, 10.133.166.16, 10.133.166.64 | S6: yes | T6: yes | U6: no
A7: ad68f68c-c68b-51ba-aa31-ff07cf879e70 | B7: osttra-dnm-uat-emr-instances | C7: cloud ticket raised i we do not have sufficient access(CLOUD-9647) | D7: AWS | E7: i-00def31df3797e634 | F7: Linux | G7: Active | H7: {"Category":"credit risk","CostCenter":"Osttra","Deployment_Method":"Terragrunt","Description":"this resource is created for dnm via terraform or terragrunt","Email":"shiva.sharma@osttra.com","Environment":"uat","Name":"osttra-dnm-uat-emr-instances","Owner":"Shiva Sharma","Project":"dnm","RepoUrl":"https://github.com/osttra/terraform-dnm-provisioning","aws:elasticmapreduce:instance-group-role":"CORE","aws:elasticmapreduce:job-flow-id":"j-6Y9REDA2E8B9"} | I7: a5c5f28c-1da9-5f94-9411-518634cf0754 | J7: us-east-1 (801519552827) | K7: 049eb668-9113-549b-84f2-6f8412fbcd60 | L7: Amazon Linux 2023 (osttra-dnm-uat-emr-instances) | M7: 2023.6.20250218 (Amazon Linux) | N7: 71a107e4-5845-5e3b-a255-42d25844eb5d | O7: aws-cr-uat | P7: 801519552827 | Q7: e5f109db-61cd-59b4-98af-5d07f999ac0b | R7: 10.133.176.102 | S7: No | T7: No | U7: Yes
A8: c975acda-856d-5f33-9e86-1d9902bfe2c5 | B8: osttra-dnm-uat-emr-instances | C8: installed | D8: AWS | E8: wiz-representative##Ephemeral_aws:elasticmapreduce:job-flow-id_j-6Y9REDA2E8B9 | F8: Linux | G8: Active | H8: {"Category":"credit risk","CostCenter":"Osttra","Deployment_Method":"Terragrunt","Description":"this resource is created for dnm via terraform or terragrunt","Email":"shiva.sharma@osttra.com","Environment":"uat","Name":"osttra-dnm-uat-emr-instances","Owner":"Shiva Sharma","Project":"dnm","RepoUrl":"https://github.com/osttra/terraform-dnm-provisioning","aws:elasticmapreduce:instance-group-role":"CORE","aws:elasticmapreduce:job-flow-id":"j-6Y9REDA2E8B9"} | I8: a5c5f28c-1da9-5f94-9411-518634cf0754 | J8: us-east-1 (801519552827) | K8: 69c9f7e6-3122-519a-be06-bfc1fcfc590c | L8: Amazon Linux 2023 (osttra-dnm-uat-emr-instances) | M8: 2023.6.20250218 (Amazon Linux) | N8: 71a107e4-5845-5e3b-a255-42d25844eb5d | O8: aws-cr-uat | P8: 801519552827 | Q8: 3a3f14b9-0244-5ea9-a545-0ed2fde1093b | R8: 10.133.176.15, 10.133.176.50, 10.133.176.91 | S8: no | T8: no | U8: Yes
A9: c04c7a46-2539-51e1-965f-0c2f2c007c56 | B9: Bastion-node | D9: AWS | E9: i-081741ef971de8ae3 | F9: Linux | G9: Active | H9: {"Name":"Bastion-node"} | I9: 62f737fe-47e4-550d-93eb-1824528b243a | J9: us-east-1 (471112977791) | K9: 3164c603-58cd-5f84-b6ee-80a68b5cbcbf | L9: Amazon Linux 2023 (Bastion-node) | M9: 2023.5.20240916 (Amazon Linux) | N9: 009871ae-18cd-5805-a399-83e4c9c92fca | O9: aws-diamond-uat | P9: 471112977791 | Q9: deea4713-ef33-5b20-b854-1ea864ae126b | R9: 10.136.1.213 | S9: Yes | T9: Yes | U9: No
A10: 0511b40c-f737-537f-ad6f-a2791b072ff3 | B10: bastion-node | C10: already installed | D10: AWS | E10: i-0526f0681a552872e | F10: Linux | G10: Active | H10: {"Name":"bastion-node","aws:eks:cluster-name":"uat","eks:cluster-name":"uat","eks:nodegroup-name":"fx-baton-uat","k8s.io/cluster-autoscaler/enabled":"true","k8s.io/cluster-autoscaler/uat":"owned","kubernetes.io/cluster/uat":"owned"} | I10: e9c531ac-4742-5944-8352-0ba6c09fe76e | J10: us-west-2 (471112977791) | K10: 4cc2d74d-b305-592d-9587-b2c23684f843 | L10: Amazon Linux 2 (bastion-node) | M10: 2 (Karoo) | N10: 009871ae-18cd-5805-a399-83e4c9c92fca | O10: aws-diamond-uat | P10: 471112977791 | Q10: 12ca29b8-347c-5a54-845c-8ee0bae2a68e | R10: 10.136.16.104, 10.136.16.118, 10.136.16.124, 10.136.16.167, 10.136.16.195, 10.136.16.228, 10.136.16.231, 10.136.16.240, 10.136.16.241, 10.136.16.28, 10.136.16.54, 10.136.16.56, 10.136.16.83, 10.136.16.86, 10.136.17.100, 10.136.17.112, 10.136.17.123, 10.136.17.14, 10.136.17.151, 10.136.17.174, 10.136.17.182, 10.136.17.203, 10.136.17.220, 10.136.17.223, 10.136.17.242, 10.136.17.252, 10.136.17.254, 10.136.17.64, 10.136.17.7, 10.136.17.74, 10.136.17.90 | S10: no | T10: no | U10: Yes
A11: 5fca62e6-448a-5c92-b356-c990c416ded6 | B11: sftp-server | C11: cloud ticket raised i we do not have sufficient access(CLOUD-9647) | D11: AWS | E11: i-0001c34108da47a53 | F11: Linux | G11: Active | H11: {"Name":"sftp-server"} | I11: 03c0fcd3-3e8b-5dea-84af-ff0f603205d0 | J11: us-east-1 (727635021987) | K11: 4cb338af-3dd1-5ffc-8b01-ceba9a344d93 | L11: Amazon Linux 2 (sftp-server) | M11: 2 (Karoo) | N11: 6812388b-5b6a-57d6-851f-fac49d23ef94 | O11: aws-fs-dev | P11: 727635021987 | Q11: b55907ba-70f2-57ce-b39d-e42babb73f7b | R11: 10.134.3.113 | S11: No | T11: No | U11: Yes
A12: b02461ba-c880-5b27-a2b3-d020df06dfc8 | B12: test-automation | D12: AWS | E12: i-0c6778b2ebd40532a | F12: Windows | G12: Active | H12: {"Name":"test-automation"} | I12: 03c0fcd3-3e8b-5dea-84af-ff0f603205d0 | J12: us-east-1 (727635021987) | K12: 79e76412-d8f6-5682-a68a-4c50c466543a | L12: Windows Server 2022 (test-automation) | M12: 20348.1129 | N12: 6812388b-5b6a-57d6-851f-fac49d23ef94 | O12: aws-fs-dev | P12: 727635021987 | Q12: cb320047-5b8e-5a8d-9dcd-96ef545390dd | R12: 10.134.3.95 | S12: No | T12: No | U12: Yes
A13: 58ab542c-82f2-5f6c-8fcb-09a850c34467 | B13: test-crds-cfd-server | C13: cloud ticket raised i we do not have sufficient access(CLOUD-9647) | D13: AWS | E13: i-0bf88df3b742a8dab | F13: Linux | G13: Active | H13: {"Availability":"not_24x7","CostCenter":"Osttra","Environment":"qa","Name":"test-crds-cfd-server","Owner":"Deependra Agarwal","Project":"crds-cfd","value":"test-crds-cfd-server"} | I13: 070d386f-9ff2-5015-b967-e84b2908257c | J13: us-east-1 (707300401698) | K13: 7c1795ac-af6e-5d03-90ee-52a99894e6ab | L13: Amazon Linux 2023 (test-crds-cfd-server) | M13: 2023.6.20250203 (Amazon Linux) | N13: 138e5b65-0ad9-50d8-9976-a6025675b72d | O13: aws-fs-qa | P13: 707300401698 | Q13: ec96e1c8-09c7-5a4b-8070-fcd340278d99 | R13: 10.134.152.115 | S13: No | T13: No | U13: Yes
A14: 523294c7-3ef4-572e-8b4d-8abff6f033d7 | B14: ue1pl-con-ftp-asg | D14: AWS | E14: i-0279632ed55437f9b | F14: Linux | G14: Active | H14: {"Availability":"24x7","Category":"traiana","CostCenter":"Osttra","DeploymentMethod":"Terragrunt","Deployment_Method":"Terragrunt","Description":"This resource is created for tpcore-dmz via terragrunt","Email":"osttra-cloud-enablement@osttra.com","Environment":"ue1p","Name":"ue1pl-con-ftp-asg","Owner":"Cloud Engineering","Project":"tpcore-dmz","RepoUrl":"https://github.com/osttra/terraform-aws-tpcore-dmz-provisioning","aws:ec2launchtemplate:id":"lt-0a3fd5b3a4b0a1ccc","aws:ec2launchtemplate:version":"1"} | I14: 35f0e323-0818-5f67-a7c3-bf95849762e6 | J14: us-east-1 (767397888233) | K14: 42074666-16f0-5a1e-93f9-738e4f528325 | L14: Linux Red Hat (ue1pl-con-ftp-asg) | M14: 9.4 | N14: 1103850b-f940-524b-a276-27930abe7533 | O14: aws-osttra-dmz-prod | P14: 767397888233 | Q14: 6fbe97e3-ed5e-5eae-a250-86545af35bd3 | R14: 10.195.57.234 | S14: Yes | T14: Yes | U14: No
A15: 1f93d62f-7d89-582b-b9c9-6ae97a59c2b0 | B15: ue1pl-con-ftp03 | D15: AWS | E15: i-029cb82491d3d119f | F15: Linux | G15: Active | H15: {"Category":"traiana","CostCenter":"Osttra","Deployment_Method":"Terragrunt","Description":"This resource is created for tpcore-dmz via terragrunt","Email":"osttra-cloud-enablement@osttra.com","Environment":"ue1p","Name":"ue1pl-con-ftp03","Owner":"Cloud Engineering","Project":"tpcore-dmz","RepoUrl":"https://github.com/osttra/terraform-aws-tpcore-dmz-provisioning"} | I15: 35f0e323-0818-5f67-a7c3-bf95849762e6 | J15: us-east-1 (767397888233) | K15: 94a1aacf-44c8-5f7f-9da1-c1fe8bca5f97 | L15: Linux Red Hat (ue1pl-con-ftp03) | M15: 9.4 | N15: 1103850b-f940-524b-a276-27930abe7533 | O15: aws-osttra-dmz-prod | P15: 767397888233 | Q15: a37bf00a-7b6d-51e9-aeb6-5e48e1904f6f | R15: 10.195.54.170 | S15: Yes | T15: Yes | U15: No
A16: 140e3ba6-594b-5d1b-a826-6e740da90f86 | B16: ue1pl-con-ftp02 | D16: AWS | E16: i-02bfbbd6d4d6be083 | F16: Linux | G16: Active | H16: {"Category":"traiana","CostCenter":"Osttra","Deployment_Method":"Terragrunt","Description":"This resource is created for tpcore-dmz via terragrunt","Email":"osttra-cloud-enablement@osttra.com","Environment":"ue1p","Name":"ue1pl-con-ftp02","Owner":"Cloud Engineering","Project":"tpcore-dmz","RepoUrl":"https://github.com/osttra/terraform-aws-tpcore-dmz-provisioning"} | I16: 35f0e323-0818-5f67-a7c3-bf95849762e6 | J16: us-east-1 (767397888233) | K16: f337fae4-9cea-5297-981f-be9d692c7334 | L16: Linux Red Hat (ue1pl-con-ftp02) | M16: 9.4 | N16: 1103850b-f940-524b-a276-27930abe7533 | O16: aws-osttra-dmz-prod | P16: 767397888233 | Q16: 8da95ca3-cc35-57ca-99e2-34d9bbfdd3dc | R16: 10.195.57.252 | S16: Yes | T16: Yes | U16: No
A17: 4baaaeab-8fab-50b9-b215-29a286f9f897 | B17: ue1pl-sh2-mq01 | D17: AWS | E17: i-02e57e4d38f0e4c5d | F17: Linux | G17: Active | H17: {"Category":"traiana","CostCenter":"Osttra","Deployment_Method":"Terragrunt","Description":"this resource is created for tpcore-dmz via terraform or terragrunt","Email":"osttra-cloud-enablement@osttra.com","Environment":"ue1p","Name":"ue1pl-sh2-mq01","Owner":"Cloud Engineering","Project":"tpcore-dmz","RepoUrl":"https://github.com/osttra/terraform-aws-tpcore-dmz-provisioning","ec2-backup":"false","fw_app":"mq-sh2","fw_default":"true","fw_env":"prod","fw_nat":"shared"} | I17: 35f0e323-0818-5f67-a7c3-bf95849762e6 | J17: us-east-1 (767397888233) | K17: 3056aab4-b6a2-52de-b264-9b26a28ab1dc | L17: Linux Red Hat (ue1pl-sh2-mq01) | M17: 9.4 | N17: 1103850b-f940-524b-a276-27930abe7533 | O17: aws-osttra-dmz-prod | P17: 767397888233 | Q17: 5fa3aca0-5d20-55ef-a9c3-0775561e1bca | R17: 10.195.55.193 | S17: Yes | T17: Yes | U17: No
A18: bb8782b6-449a-5d8a-b1d6-dee4b7daa574 | B18: ue1pl-lh-mqext01 | D18: AWS | E18: i-0365a7135132818de | F18: Linux | G18: Active | H18: {"Category":"traiana","CostCenter":"Osttra","Deployment_Method":"Terragrunt","Description":"this resource is created for tpcore-dmz via terraform or terragrunt","Email":"osttra-cloud-enablement@osttra.com","Environment":"ue1p","Name":"ue1pl-lh-mqext01","Owner":"Cloud Engineering","Project":"tpcore-dmz","RepoUrl":"https://github.com/osttra/terraform-aws-tpcore-dmz-provisioning","cost-center:app":"limithub","cost-center:category":"app","cost-center:email":"dl-limithub-development@osttra.com","cost-center:env":"prod","cost-center:owner":"limithub-team","ec2-backup":"true","fw_app":"mqext","fw_default":"true","fw_env":"prod","fw_nat":"limithub"} | I18: 35f0e323-0818-5f67-a7c3-bf95849762e6 | J18: us-east-1 (767397888233) | K18: fec69c68-fbd8-577a-a0cc-64e49c1a9bff | L18: Linux Red Hat (ue1pl-lh-mqext01) | M18: 9.4 | N18: 1103850b-f940-524b-a276-27930abe7533 | O18: aws-osttra-dmz-prod | P18: 767397888233 | Q18: 6cb2cbad-d8f0-5cc3-8f17-a2a814f7f0ee | R18: 10.195.54.124 | S18: Yes | T18: Yes | U18: No
A19: 99bcdf5c-5259-5363-9599-ff4a7dce61db | B19: ue1pl-sh2-mq02 | D19: AWS | E19: i-0375514b5dc9e84f0 | F19: Linux | G19: Active | H19: {"Category":"traiana","CostCenter":"Osttra","Deployment_Method":"Terragrunt","Description":"this resource is created for tpcore-dmz via terraform or terragrunt","Email":"osttra-cloud-enablement@osttra.com","Environment":"ue1p","Name":"ue1pl-sh2-mq02","Owner":"Cloud Engineering","Project":"tpcore-dmz","RepoUrl":"https://github.com/osttra/terraform-aws-tpcore-dmz-provisioning","ec2-backup":"false","fw_app":"mq-sh2","fw_default":"true","fw_env":"prod","fw_nat":"shared"} | I19: 35f0e323-0818-5f67-a7c3-bf95849762e6 | J19: us-east-1 (767397888233) | K19: fb042d39-d3e6-5513-83cf-fb220983e380 | L19: Linux Red Hat (ue1pl-sh2-mq02) | M19: 9.4 | N19: 1103850b-f940-524b-a276-27930abe7533 | O19: aws-osttra-dmz-prod | P19: 767397888233 | Q19: 08f8b97e-36bf-5e4a-8000-c3fec88a4b09 | R19: 10.195.57.44 | S19: Yes | T19: Yes | U19: No
A20: 9191838d-89ad-547f-a96a-c7a3ccfe41b2 | B20: ue1p-inf-phdc2 | D20: AWS | E20: i-03d2b3c08cec533c0 | F20: Windows | G20: Active | H20: {"Name":"ue1p-inf-phdc2"} | I20: 35f0e323-0818-5f67-a7c3-bf95849762e6 | J20: us-east-1 (767397888233) | K20: 091f0027-b869-50b6-be32-d9931dde1bee | L20: Windows Server 2019 (ue1p-inf-phdc2) | M20: 17763.8511 | N20: 1103850b-f940-524b-a276-27930abe7533 | O20: aws-osttra-dmz-prod | P20: 767397888233 | Q20: 4eba58d6-12d2-5f9c-a3f8-fa10ca6015a4 | R20: 10.195.56.17 | S20: Yes | T20: Yes | U20: No
A21: 19f38a06-ccd9-5b03-9eb7-61ddd5ad1f1a | B21: ue1pl-sh-test-mq01 | D21: AWS | E21: i-055817efcf1837186 | F21: Linux | G21: Active | H21: {"Category":"traiana","CostCenter":"Osttra","Deployment_Method":"Terragrunt","Description":"This resource is created for tpcore-dmz via terragrunt","Email":"osttra-cloud-enablement@osttra.com","Environment":"ue1p","Name":"ue1pl-sh-test-mq01","Owner":"Cloud Engineering","Project":"tpcore-dmz","RepoUrl":"https://github.com/osttra/terraform-aws-tpcore-dmz-provisioning","ec2-backup":"false","fw_app":"mq-sh-test","fw_default":"true","fw_env":"prod","fw_nat":"shared"} | I21: 35f0e323-0818-5f67-a7c3-bf95849762e6 | J21: us-east-1 (767397888233) | K21: 42377173-15a3-503b-9cde-b0a78cea51ce | L21: Linux Red Hat (ue1pl-sh-test-mq01) | M21: 9.4 | N21: 1103850b-f940-524b-a276-27930abe7533 | O21: aws-osttra-dmz-prod | P21: 767397888233 | Q21: 1ffdbc78-80c2-5b7d-a9e6-cc7e6963394d | R21: 10.195.54.252 | S21: Yes | T21: Yes | U21: No
A22: 92515cb9-499b-56e6-aed2-e8f4c95f06e9 | B22: ue1pl-sh-test-mq02 | D22: AWS | E22: i-06a0c15220549e0b4 | F22: Linux | G22: Active | H22: {"Category":"traiana","CostCenter":"Osttra","Deployment_Method":"Terragrunt","Description":"This resource is created for tpcore-dmz via terragrunt","Email":"osttra-cloud-enablement@osttra.com","Environment":"ue1p","Name":"ue1pl-sh-test-mq02","Owner":"Cloud Engineering","Project":"tpcore-dmz","RepoUrl":"https://github.com/osttra/terraform-aws-tpcore-dmz-provisioning","ec2-backup":"false","fw_app":"mq-sh-test","fw_default":"true","fw_env":"prod","fw_nat":"shared"} | I22: 35f0e323-0818-5f67-a7c3-bf95849762e6 | J22: us-east-1 (767397888233) | K22: 0264722b-9af3-50c8-8d4f-770c8d8fbb20 | L22: Linux Red Hat (ue1pl-sh-test-mq02) | M22: 9.4 | N22: 1103850b-f940-524b-a276-27930abe7533 | O22: aws-osttra-dmz-prod | P22: 767397888233 | Q22: bf8cfa69-8744-5a5f-8fb9-911f71ca725c | R22: 10.195.56.243 | S22: Yes | T22: Yes | U22: No
A23: fc7b36e3-f35a-5f54-a005-56d218e25854 | B23: ue1p-inf-phdc1 | D23: AWS | E23: i-0736c3193908c8e61 | F23: Windows | G23: Active | H23: {"Name":"ue1p-inf-phdc1"} | I23: 35f0e323-0818-5f67-a7c3-bf95849762e6 | J23: us-east-1 (767397888233) | K23: 4add5b1c-4711-5b47-8231-4a2f5c3ea85d | L23: Windows Server 2019 (ue1p-inf-phdc1) | M23: 17763.8511 | N23: 1103850b-f940-524b-a276-27930abe7533 | O23: aws-osttra-dmz-prod | P23: 767397888233 | Q23: 3e380545-4ffc-55f5-b41e-e5d1a3d88771 | R23: 10.195.54.95 | S23: Yes | T23: Yes | U23: No
A24: 2350365a-542d-58aa-8aeb-030d980caa50 | B24: ue1pw-con-ftp2 | D24: AWS | E24: i-07e68cc69ac89aa75 | F24: Windows | G24: Active | H24: {"Name":"ue1pw-con-ftp2"} | I24: 35f0e323-0818-5f67-a7c3-bf95849762e6 | J24: us-east-1 (767397888233) | K24: 9c4e2bdf-753c-5a68-ab14-01c437990ea7 | L24: Windows Server 2019 (ue1pw-con-ftp2) | M24: 17763.6893 | N24: 1103850b-f940-524b-a276-27930abe7533 | O24: aws-osttra-dmz-prod | P24: 767397888233 | Q24: d25b1ff3-3616-57cb-bc09-4883e3b766e4 | R24: 10.195.55.95 | S24: Yes | T24: Yes | U24: No
A25: 8c648e9d-2c5f-51e6-9975-632395d8def2 | B25: nginx-fsx-1 | D25: AWS | E25: i-09b67a718092cd38a | F25: Linux | G25: Active | H25: {"Name":"nginx-fsx-1"} | I25: 35f0e323-0818-5f67-a7c3-bf95849762e6 | J25: us-east-1 (767397888233) | K25: 540c2c24-125e-5ea7-b85c-46c1b6093825 | L25: Amazon Linux 2023 (nginx-fsx-1) | M25: 2023.10.20260302 (Amazon Linux) | N25: 1103850b-f940-524b-a276-27930abe7533 | O25: aws-osttra-dmz-prod | P25: 767397888233 | Q25: a484ae36-816b-55f7-b348-ae12a3a623e7 | R25: 10.195.54.239 | S25: Yes | T25: Yes | U25: No
... A47: b5a6324b-f011-5847-883b-1fe46450aad9 | B47: ue2pl-lh-mqext02 | D47: AWS | E47: i-0e121cd32606f802e | F47: Linux | G47: Active | H47: {"Category":"traiana","CostCenter":"Osttra","Deployment_Method":"Terragrunt","Description":"this resource is created for tpcore-dmz via terraform or terragrunt","Email":"osttra-cloud-enablement@osttra.com","Environment":"ue2p","Name":"ue2pl-lh-mqext02","Owner":"Cloud Engineering","Project":"tpcore-dmz","RepoUrl":"https://github.com/osttra/terraform-aws-tpcore-dmz-provisioning","cost-center:app":"limithub","cost-center:category":"app","cost-center:email":"dl-limithub-development@osttra.com","cost-center:env":"prod","cost-center:owner":"limithub-team","ec2-backup":"true","fw_app":"mqext","fw_default":"true","fw_env":"prod","fw_nat":"limithub"} | I47: d1052f70-beb0-5b2e-8d0b-2b78fe8a5820 | J47: us-east-2 (767397888233) | K47: fb3c2493-e9da-5e33-bf18-fd2a77740493 | L47: Linux Red Hat (ue2pl-lh-mqext02) | M47: 9.4 | N47: 1103850b-f940-524b-a276-27930abe7533 | O47: aws-osttra-dmz-prod | P47: 767397888233 | Q47: 08ec830f-ca22-5e38-b0cc-f3d0bcdc865f | R47: 10.188.137.109 | S47: Yes | T47: Yes | U47: No
A48: a6e6d9b2-8ed1-5c7b-b119-fdcccdd0e129 | B48: Satellite-server | C48: already installed | D48: AWS | E48: i-0e3190d3603f5c714 | F48: Linux | G48: Active | H48: {"Name":"Satellite-server"} | I48: d1052f70-beb0-5b2e-8d0b-2b78fe8a5820 | J48: us-east-2 (767397888233) | K48: 5b9af5c6-ea26-5ab2-ae64-3e970f585be3 | L48: Linux Red Hat (Satellite-server) | M48: 9.5 | N48: 1103850b-f940-524b-a276-27930abe7533 | O48: aws-osttra-dmz-prod | P48: 767397888233 | Q48: 3e1f02fe-1531-5b0d-b090-8e6f2366e220 | R48: 10.188.134.84 | S48: no | T48: no | U48: Yes
A49: 271c2ae4-099c-5307-87c1-7f3678c0c1cc | B49: ue2pl-sh2-mq02 | D49: AWS | E49: i-0e73505053711e0a9 | F49: Linux | G49: Active | H49: {"Category":"traiana","CostCenter":"Osttra","Deployment_Method":"Terragrunt","Description":"this resource is created for tpcore-dmz via terraform or terragrunt","Email":"osttra-cloud-enablement@osttra.com","Environment":"ue2p","Name":"ue2pl-sh2-mq02","Owner":"Cloud Engineering","Project":"tpcore-dmz","RepoUrl":"https://github.com/osttra/terraform-aws-tpcore-dmz-provisioning","ec2-backup":"false","fw_app":"mq-sh2","fw_default":"true","fw_env":"prod","fw_nat":"shared"} | I49: d1052f70-beb0-5b2e-8d0b-2b78fe8a5820 | J49: us-east-2 (767397888233) | K49: 95b4fa93-0791-5d47-9620-8b7d4226d1d0 | L49: Linux Red Hat (ue2pl-sh2-mq02) | M49: 9.4 | N49: 1103850b-f940-524b-a276-27930abe7533 | O49: aws-osttra-dmz-prod | P49: 767397888233 | Q49: 116ecdfd-9ffd-578f-aaed-e240f96fe542 | R49: 10.188.137.72 | S49: Yes | T49: Yes | U49: No
A50: 26bd8694-6fbb-58ee-bb8b-253d034463ce | B50: ue2ul-ust-mqe1 | D50: AWS | E50: i-0ef74a673e118d602 | F50: Linux | G50: Active | H50: {"Category":"traiana","CostCenter":"Osttra","Deployment_Method":"Terragrunt","Description":"this resource is created for tpcore-dmz via terraform or terragrunt","Email":"osttra-cloud-enablement@osttra.com","Environment":"ue2u","Name":"ue2ul-ust-mqe1","Owner":"Cloud Engineering","Project":"tpcore-dmz","RepoUrl":"https://github.com/osttra/terraform-aws-tpcore-dmz-provisioning"} | I50: d1052f70-beb0-5b2e-8d0b-2b78fe8a5820 | J50: us-east-2 (767397888233) | K50: 93c7454d-4050-5aa0-8312-d3d15d1c367e | L50: Linux Red Hat (ue2ul-ust-mqe1) | M50: 9.4 | N50: 1103850b-f940-524b-a276-27930abe7533 | O50: aws-osttra-dmz-prod | P50: 767397888233 | Q50: f7336f1f-4cf7-5de8-846f-baf744f0d14c | R50: 10.188.135.165 | S50: Yes | T50: Yes | U50: No
A51: 16ab6750-62d5-5f75-902f-71e87ffb2880 | B51: ue2p-ext-prmdc2 | D51: AWS | E51: i-0f146150840217527 | F51: Windows | G51: Active | H51: {"Name":"ue2p-ext-prmdc2"} | I51: d1052f70-beb0-5b2e-8d0b-2b78fe8a5820 | J51: us-east-2 (767397888233) | K51: e66c574c-dd08-54d0-b268-82ab37275d1f | L51: Windows Server 2019 (ue2p-ext-prmdc2) | M51: 17763.8511 | N51: 1103850b-f940-524b-a276-27930abe7533 | O51: aws-osttra-dmz-prod | P51: 767397888233 | Q51: 4e5647b8-3513-5610-8d24-314900222c6a | R51: 10.188.136.200 | S51: Yes | T51: Yes | U51: No
A52: a66e18b1-565b-55ad-83ba-94d577dba930 | B52: ue2p-inf-phdc2 | D52: AWS | E52: i-0f71f067ab9f5dffd | F52: Windows | G52: Active | H52: {"Name":"ue2p-inf-phdc2"} | I52: d1052f70-beb0-5b2e-8d0b-2b78fe8a5820 | J52: us-east-2 (767397888233) | K52: 57701e6a-562a-51b6-a5a5-2e0e644c6a85 | L52: Windows Server 2019 (ue2p-inf-phdc2) | M52: 17763.8511 | N52: 1103850b-f940-524b-a276-27930abe7533 | O52: aws-osttra-dmz-prod | P52: 767397888233 | Q52: b5f4a5a9-33d9-5ba9-b7b0-bf8a53f99382 | R52: 10.188.137.20 | S52: Yes | T52: Yes | U52: No
A53: 6a64fddc-822f-5b97-9cac-034b653de04e | B53: ue2p-inf-lum3 | D53: AWS | E53: i-0f8a0f98b7fc12229 | F53: Linux | G53: Active | H53: {"Category":"traiana-dr","CostCenter":"Osttra","Deployment_Method":"Terragrunt","Description":"this resource is created for tpcore-dmz via terraform or terragrunt","Email":"osttra-cloud-enablement@osttra.com","Environment":"dr","Name":"ue2p-inf-lum3","Owner":"Cloud Engineering","Project":"tpcore-dmz","RepoUrl":"https://github.com/osttra/terraform-aws-tpcore-dmz-provisioning"} | I53: d1052f70-beb0-5b2e-8d0b-2b78fe8a5820 | J53: us-east-2 (767397888233) | K53: bcbf1906-d860-570f-9dab-9423d4d52e15 | L53: Linux Red Hat (ue2p-inf-lum3) | M53: 9.4 | N53: 1103850b-f940-524b-a276-27930abe7533 | O53: aws-osttra-dmz-prod | P53: 767397888233 | Q53: ab7f8570-d385-5163-8975-b3168bb93824 | R53: 10.188.135.203 | S53: Yes | T53: Yes | U53: No
A54: ca665d7e-1f27-5195-8cf6-609bb295e80b | B54: test-webserver-tsa | C54: working with network team to get access | D54: AWS, Networking | E54: i-0bedc331766074afc | F54: Linux | G54: Active | H54: {"CostCenter":"Osttra","Deployment_Method":"Terragrunt","Description":"This resource is created for osttra-network","Email":"network@osttra.com","Environment":"PROD","Name":"test-webserver-tsa","Owner":"osttra-network","Project":"osttra-network"} | I54: 36274844-cf73-5b85-9ee5-b3549348b79d | J54: ap-south-1 (161441385277) | K54: 7ef9f144-9da7-5dc1-9bbe-6b75e8f54982 | L54: Amazon Linux 2023 (test-webserver-tsa) | M54: 2023.5.20240708 (Amazon Linux) | N54: a918d5cb-5ffb-508d-93bd-76abaf4294b5 | O54: aws-osttra-network | P54: 161441385277 | Q54: 8409aa29-c74c-5148-a8fe-8f7ccb00d004 | R54: 10.196.1.81, 15.206.75.153, ec2-15-206-75-153.ap-south-1.compute.amazonaws.com | S54: No | T54: No | U54: Yes
A55: edb8d9b3-2048-5038-b4b0-af07122f8da0 | B55: test-ubuntu-alloy-vm | C55: working with network team to get access | D55: AWS, Networking | E55: i-038f7db7c40c7d3ce | F55: Linux | G55: Active | H55: {"Name":"test-ubuntu-alloy-vm"} | I55: f645dd2c-054d-5e23-9b46-57eceac46ebc | J55: eu-north-1 (161441385277) | K55: 3b7fee0b-3576-5b81-b15f-55a987418a8e | L55: Linux Ubuntu (test-ubuntu-alloy-vm) | M55: 24.04.2 | N55: a918d5cb-5ffb-508d-93bd-76abaf4294b5 | O55: aws-osttra-network | P55: 161441385277 | Q55: be4fcf9d-6a1f-530d-9979-df772cfb3355 | R55: 10.196.254.94 | S55: No | T55: No | U55: Yes
A56: d6fcd538-84c8-585a-9afa-4478851eb970 | B56: osttra-network-prod-syslog-eu-west-1a | C56: working with network team to get access | D56: AWS, Networking | E56: i-00529f1f6530063aa | F56: Linux | G56: Active | H56: {"AccountName":"aws-osttra-network","AccountNo":"161441385277","CostCenter":"Osttra","Deployment_Method":"Terragrunt","Description":"This resource is created for osttra-network via terraform or terragrunt","Email":"network@osttra.com","Environment":"Prod","Name":"osttra-network-prod-syslog-eu-west-1a","Owner":"OSTTRA Network","Project":"osttra-network","RepoUrl":"https://github.com/osttra/aws-network-deploy"} | I56: 57553cad-b73c-5cf7-a1de-ce0558cc0ba7 | J56: eu-west-1 (161441385277) | K56: d5a165b2-0481-5941-95fb-6dd6023e124c | L56: Linux Ubuntu (osttra-network-prod-syslog-eu-west-1a) | M56: 22.04.4 | N56: a918d5cb-5ffb-508d-93bd-76abaf4294b5 | O56: aws-osttra-network | P56: 161441385277 | Q56: 5782eaa1-f5c3-5052-ad93-0ca9f770fcb7 | R56: 10.196.253.12 | S56: No | T56: No | U56: Yes
A57: 2fc494d2-fae4-5690-8e66-2ba7b71be752 | B57: osttra-network-prod-zabbix-server-eu-west-1a | C57: working with network team to get access | D57: AWS, Networking | E57: i-03e3344fbdef07ec3 | F57: Linux | G57: Active | H57: {"AccountName":"aws-osttra-network","AccountNo":"161441385277","CostCenter":"Osttra","Deployment_Method":"Terragrunt","Description":"This resource is created for osttra-network via terraform or terragrunt","Email":"network@osttra.com","Environment":"Prod","Name":"osttra-network-prod-zabbix-server-eu-west-1a","Owner":"OSTTRA Network","Project":"osttra-network","RepoUrl":"https://github.com/osttra/aws-network-deploy","aws_backup_plan":"backup_daily-retention_weekly"} | I57: 57553cad-b73c-5cf7-a1de-ce0558cc0ba7 | J57: eu-west-1 (161441385277) | K57: ed176991-d138-537f-8322-afddbde426b6 | L57: Linux Ubuntu (osttra-network-prod-zabbix-server-eu-west-1a) | M57: 20.04.6 | N57: a918d5cb-5ffb-508d-93bd-76abaf4294b5 | O57: aws-osttra-network | P57: 161441385277 | Q57: 3790ef3b-0f1f-5187-af48-2c26ba9065b6 | R57: 10.196.252.199 | S57: No | T57: No | U57: Yes
A58: 6a2cbd33-77d6-52b8-82cf-57368c189864 | B58: Network_Automation_GITHUB_Runner_debian | C58: working with network team to get access | D58: AWS, Networking | E58: i-05166dfc3bdff5904 | F58: Linux | G58: Active | H58: {"CostCenter":"Osttra","Deployment_Method":"Terragrunt","Description":"This resource is created for lets_encrypt testing","Email":"network@osttra.com","Environment":"TEST","Name":"Network_Automation_GITHUB_Runner_debian","Owner":"osttra-network","Project":"osttra-network","RepoUrl":"Network"} | I58: 57553cad-b73c-5cf7-a1de-ce0558cc0ba7 | J58: eu-west-1 (161441385277) | K58: 26f83fae-716a-5779-bd7d-e9f9757c686e | L58: Linux Debian (Network_Automation_GITHUB_Runner_debian) | M58: 12.13 | N58: a918d5cb-5ffb-508d-93bd-76abaf4294b5 | O58: aws-osttra-network | P58: 161441385277 | Q58: 1f7a8423-d4c3-5e7e-b5a5-a9ad6d59a383 | R58: 10.196.252.44 | S58: No | T58: No | U58: Yes
A59: aa1bc54c-6365-582f-b301-16213ffe3455 | B59: osttra-network-prod-ntp-eu-west-1a | C59: working with network team to get access | D59: AWS, Networking | E59: i-079cad43e82b95e0f | F59: Linux | G59: Active | H59: {"AccountName":"aws-osttra-network","AccountNo":"161441385277","CostCenter":"Osttra","Deployment_Method":"Terragrunt","Description":"This resource is created for osttra-network via terraform or terragrunt","Email":"network@osttra.com","Environment":"Prod","Name":"osttra-network-prod-ntp-eu-west-1a","Owner":"OSTTRA Network","Project":"osttra-network","RepoUrl":"https://github.com/osttra/aws-network-deploy"} | I59: 57553cad-b73c-5cf7-a1de-ce0558cc0ba7 | J59: eu-west-1 (161441385277) | K59: 452365e7-ebb2-50fc-b09e-8960a4c9f54b | L59: Linux Ubuntu (osttra-network-prod-ntp-eu-west-1a) | M59: 22.04.4 | N59: a918d5cb-5ffb-508d-93bd-76abaf4294b5 | O59: aws-osttra-network | P59: 161441385277 | Q59: 2a129868-c7d5-59b2-8d8f-f126df6c11f2 | R59: 10.196.252.105 | S59: No | T59: No | U59: Yes
A60: 11434022-ecbd-5d94-8434-619eba7f8660 | B60: osttra-network-prod-ntp-eu-west-1b | C60: working with network team to get access | D60: AWS, Networking | E60: i-0913264e9c0836942 | F60: Linux | G60: Active | H60: {"AccountName":"aws-osttra-network","AccountNo":"161441385277","CostCenter":"Osttra","Deployment_Method":"Terragrunt","Description":"This resource is created for osttra-network via terraform or terragrunt","Email":"network@osttra.com","Environment":"Prod","Name":"osttra-network-prod-ntp-eu-west-1b","Owner":"OSTTRA Network","Project":"osttra-network","RepoUrl":"https://github.com/osttra/aws-network-deploy"} | I60: 57553cad-b73c-5cf7-a1de-ce0558cc0ba7 | J60: eu-west-1 (161441385277) | K60: 2ef0e21b-e994-58a8-b11b-39872e2d3f4e | L60: Linux Ubuntu (osttra-network-prod-ntp-eu-west-1b) | M60: 22.04.4 | N60: a918d5cb-5ffb-508d-93bd-76abaf4294b5 | O60: aws-osttra-network | P60: 161441385277 | Q60: b9e20685-2e3e-5e0d-a184-b43e9a76a3f4 | R60: 10.196.252.121 | S60: No | T60: No | U60: Yes
A61: a1bdd559-9e51-5e91-b473-9da7bb821d27 | B61: network-web-server-instance | C61: installed now | D61: AWS, Networking | E61: i-0a7dc26511415f775 | F61: Linux | G61: Active | H61: {"CostCenter":"Osttra","DeploymentMethod":"Terragrunt","Deployment_Method":"Terragrunt","Description":"This resource is created for osttra-network via terraform or terragrunt","Email":"network@osttra.com","Environment":"PROD","Name":"network-web-server-instance","Owner":"osttra-network","Project":"osttra-network","RepoUrl":"https://github.com/osttra/aws-network-deploy"} | I61: 57553cad-b73c-5cf7-a1de-ce0558cc0ba7 | J61: eu-west-1 (161441385277) | K61: e2cd215f-170a-5c76-908a-ba9ac02937b1 | L61: Amazon Linux 2023 (network-web-server-instance) | M61: 2023.9.20250929 (Amazon Linux) | N61: a918d5cb-5ffb-508d-93bd-76abaf4294b5 | O61: aws-osttra-network | P61: 161441385277 | Q61: 487d6c4e-d52e-543d-b68c-e1a559b776ac | R61: 10.196.253.29 | S61: No | T61: No | U61: Yes
...

Sheet Sheet2
A1: VIRTUAL_MACHINE.Name | B1: POC | C1: NETWORK_ADDRESS.Name
A2: test-webserver-tsa | B2: Akshat/Ankur | C2: 10.196.1.81, 15.206.75.153, ec2-15-206-75-153.ap-south-1.compute.amazonaws.com | D2: update
A3: test-ubuntu-alloy-vm | B3: Dharamveer | C3: 10.196.254.94
A4: osttra-network-prod-syslog-eu-west-1a | B4: Dharamveer | C4: 10.196.253.12 | D4: need to check with Akshat/Ankur
A5: osttra-network-prod-zabbix-server-eu-west-1a | B5: Dharamveer | C5: 10.196.252.199 | D5: need to check with Akshat/Ankur
A6: Network_Automation_GITHUB_Runner_debian | B6: Chetan/Yash | C6: 10.196.252.44
A7: osttra-network-prod-ntp-eu-west-1a | B7: Akshat/Ankur | C7: 10.196.252.105
A8: osttra-network-prod-ntp-eu-west-1b | B8: Akshat/Ankur | C8: 10.196.252.121
A9: network-web-server-instance | B9: Rakesh Kumar | C9: 10.196.253.29 | D9: accessible
A10: osttra-network-prod-zabbix-server-eu-west-1b | B10: Akshat/Ankur | C10: 10.196.252.220
A11: Network_Automation_GITHUB_Runner | B11: Chetan/Yash | C11: 10.196.72.5 | D11: accessible
A12: osttra-network-prod-git-runner-docker-us-east-1a | B12: Chetan/Yash | C12: 10.196.72.156 | D12: accessible
A13: osttra-network-prod-ntp-us-east-1a | B13: Akshat/Ankur | C13: 10.196.72.102
A14: Network_Automation_GITHUB_Runner_2 | B14: Chetan/Yash | C14: 10.196.72.14 | D14: accessible
A15: osttra-network-prod-ntp-us-east-1b | B15: Akshat/Ankur | C15: 10.196.72.122
A16: osttra-network-prod-syslog-us-east-1a | B16: Chetan/Yash | C16: 10.196.72.142
A17: Network_Automation_GITHUB_Runner-F5 | B17: Chetan/Yash | C17: 10.196.72.7 | D17: accessible
A18: test-server-infra-vpc | B18: Discard it | C18: 10.196.112.79

Sheet Sheet4
A1: VIRTUAL_MACHINE.Name
A2: europe-west2-microgateway-instance-hb81
A3: us-east4-perf-mgw-instance-h10c
A4: gce-n-uudo-bastionhost-linux-eu-1
A5: us-east4-sic-instance-db7j
A6: osttra-sftp-gw-group
A7: us-east4-microgateway-instance-wh3x
A8: gce-p-uudo-bastionhost-linux-eu-1
A9: gce-pl-uudo-bastionhost-linux-eu-1
A10: gpu-otm-break-resolution-experiment
A11: cortex-tanium-test-gce

Sheet Non-ASG-Pivot
A1: AWS To DO | F1: GCP To Do

Sheet GCP_zone
A1: Name | B1: data | C1: Region | D1: Zone | E1: Project ID
A2: gce-p-platformtools-arc-jumphost-linux-eu-0 | B2: =VLOOKUP(A2,Sheet4!A:A,1,0) -> #N/A | C2: europe-west2 | D2: europe-west2-a | E2: prj-c-platformtools-fn8z
A3: europe-west2-microgateway-instance-hb81 | B3: =VLOOKUP(A3,Sheet4!A:A,1,0) -> europe-west2-microgateway-instance-hb81 | C3: europe-west2 | D3: europe-west2-a | E3: prj-n-swift-6f8h
A4: europe-west2-microgateway-mig | B4: =VLOOKUP(A4,Sheet4!A:A,1,0) -> #N/A | C4: europe-west2 | D4: N/A | E4: prj-n-swift-6f8h
A5: us-east4-perf-mgw-instance-h10c | B5: =VLOOKUP(A5,Sheet4!A:A,1,0) -> us-east4-perf-mgw-instance-h10c | C5: us-east4 | D5: us-east4-a | E5: prj-n-swift-6f8h
A6: us-east4-perf-mgw-mig | B6: =VLOOKUP(A6,Sheet4!A:A,1,0) -> #N/A | C6: us-east4 | D6: N/A | E6: prj-n-swift-6f8h
A7: gce-n-uudo-bastionhost-linux-eu-1 | B7: =VLOOKUP(A7,Sheet4!A:A,1,0) -> gce-n-uudo-bastionhost-linux-eu-1 | C7: us-east4 | D7: us-east4-a | E7: prj-n-uudo-qs2e
A8: gce-n-vault-jumpbox-linux-euw2 | B8: =VLOOKUP(A8,Sheet4!A:A,1,0) -> #N/A | C8: europe-west2 | D8: europe-west2-a | E8: prj-n-vault-gvez
A9: gce-n-vault-runner-linux-euw2 | B9: =VLOOKUP(A9,Sheet4!A:A,1,0) -> #N/A | C9: europe-west2 | D9: europe-west2-a | E9: prj-n-vault-gvez
A10: otm-break-resolution-experiment | B10: =VLOOKUP(A10,Sheet4!A:A,1,0) -> #N/A | C10: europe-west2 | D10: europe-west2-a | E10: prj-p-ai-glzl
A11: gce-p-bindpln-runner-linux-use4 | B11: =VLOOKUP(A11,Sheet4!A:A,1,0) -> #N/A | C11: us-east4 | D11: us-east4-a | E11: prj-p-bindpln-j70m
